[2024-05-21 20:07:03,077: INFO: main: welcome to our custom log]
[2024-05-27 10:17:31,511: INFO: common: yaml file: config\config.yaml loaded successfully]
[2024-05-27 10:17:31,521: INFO: common: yaml file: params.yaml loaded successfully]
[2024-05-27 10:18:02,451: INFO: common: yaml file: config\config.yaml loaded successfully]
[2024-05-27 10:18:02,452: INFO: common: yaml file: params.yaml loaded successfully]
[2024-05-27 10:24:10,450: INFO: common: yaml file: config\config.yaml loaded successfully]
[2024-05-27 10:24:10,467: INFO: common: yaml file: params.yaml loaded successfully]
[2024-05-27 10:32:40,221: INFO: common: yaml file: config\config.yaml loaded successfully]
[2024-05-27 10:32:40,221: INFO: common: yaml file: params.yaml loaded successfully]
[2024-05-27 10:39:42,921: INFO: common: yaml file: config\config.yaml loaded successfully]
[2024-05-27 10:39:42,937: INFO: common: yaml file: params.yaml loaded successfully]
[2024-05-27 10:39:42,937: INFO: common: created directory at: artifacts]
[2024-05-27 10:39:42,940: INFO: common: created directory at: artifacts/data_ingestion]
[2024-05-27 10:39:42,944: INFO: 986331348: Downloading data from https://drive.google.com/file/d/1vlhZ5c7abUKF8xXERIw6m9Te8fW7ohw3/view?usp=sharing into file artifacts/data_ingestion/data.zip]
[2024-05-27 11:15:20,737: INFO: common: yaml file: config\config.yaml loaded successfully]
[2024-05-27 11:15:20,747: INFO: common: yaml file: params.yaml loaded successfully]
[2024-05-27 11:15:20,750: INFO: common: created directory at: artifacts]
[2024-05-27 11:15:20,752: INFO: common: created directory at: artifacts/data_ingestion]
[2024-05-27 11:15:20,753: INFO: 986331348: Downloading data from https://drive.google.com/file/d/1vlhZ5c7abUKF8xXERIw6m9Te8fW7ohw3/view?usp=sharing into file artifacts/data_ingestion/data.zip]
[2024-05-27 11:16:32,425: INFO: 986331348: Downloaded data from https://drive.google.com/file/d/1vlhZ5c7abUKF8xXERIw6m9Te8fW7ohw3/view?usp=sharing into file artifacts/data_ingestion/data.zip]
[2024-05-27 20:13:50,216: INFO: main: >>>>>> stage Data Ingestion stage started <<<<<<]
[2024-05-27 20:13:50,216: INFO: common: yaml file: config\config.yaml loaded successfully]
[2024-05-27 20:13:50,216: INFO: common: yaml file: params.yaml loaded successfully]
[2024-05-27 20:13:50,216: INFO: common: created directory at: artifacts]
[2024-05-27 20:13:50,216: INFO: common: created directory at: artifacts/data_ingestion]
[2024-05-27 20:13:50,216: INFO: data_ingestion: Downloading data from https://drive.google.com/file/d/1vlhZ5c7abUKF8xXERIw6m9Te8fW7ohw3/view?usp=sharing into file artifacts/data_ingestion/data.zip]
[2024-05-27 20:16:05,901: INFO: data_ingestion: Downloaded data from https://drive.google.com/file/d/1vlhZ5c7abUKF8xXERIw6m9Te8fW7ohw3/view?usp=sharing into file artifacts/data_ingestion/data.zip]
[2024-05-27 20:16:06,716: INFO: main: >>>>>> stage Data Ingestion stage completed <<<<<<

x==========x]
[2024-05-30 10:08:13,433: INFO: common: yaml file: config\config.yaml loaded successfully]
[2024-05-30 10:08:13,446: INFO: common: yaml file: params.yaml loaded successfully]
[2024-05-30 10:08:13,448: INFO: common: created directory at: artifacts]
[2024-05-30 10:08:13,449: INFO: common: created directory at: artifacts/prepare_base_model]
[2024-05-30 10:14:52,594: WARNING: saving_utils: Compiled the loaded model, but the compiled metrics have yet to be built. `model.compile_metrics` will be empty until you train or evaluate the model.]
[2024-05-30 10:16:33,006: INFO: main: >>>>>> stage Data Ingestion stage started <<<<<<]
[2024-05-30 10:16:33,009: INFO: common: yaml file: config\config.yaml loaded successfully]
[2024-05-30 10:16:33,012: INFO: common: yaml file: params.yaml loaded successfully]
[2024-05-30 10:16:33,012: INFO: common: created directory at: artifacts]
[2024-05-30 10:16:33,014: INFO: common: created directory at: artifacts/data_ingestion]
[2024-05-30 10:16:33,014: INFO: data_ingestion: Downloading data from https://drive.google.com/file/d/1vlhZ5c7abUKF8xXERIw6m9Te8fW7ohw3/view?usp=sharing into file artifacts/data_ingestion/data.zip]
[2024-05-30 10:17:57,111: INFO: data_ingestion: Downloaded data from https://drive.google.com/file/d/1vlhZ5c7abUKF8xXERIw6m9Te8fW7ohw3/view?usp=sharing into file artifacts/data_ingestion/data.zip]
[2024-05-30 10:17:58,004: INFO: main: >>>>>> stage Data Ingestion stage completed <<<<<<

x==========x]
[2024-05-30 10:17:58,012: INFO: main: *******************]
[2024-05-30 10:17:58,012: INFO: main: >>>>>> stage Prepare base model started <<<<<<]
[2024-05-30 10:17:58,013: INFO: common: yaml file: config\config.yaml loaded successfully]
[2024-05-30 10:17:58,015: INFO: common: yaml file: params.yaml loaded successfully]
[2024-05-30 10:17:58,015: INFO: common: created directory at: artifacts]
[2024-05-30 10:17:58,015: INFO: common: created directory at: artifacts/prepare_base_model]
[2024-05-30 10:17:58,556: WARNING: saving_utils: Compiled the loaded model, but the compiled metrics have yet to be built. `model.compile_metrics` will be empty until you train or evaluate the model.]
[2024-05-30 10:17:58,858: INFO: main: >>>>>> stage Prepare base model completed <<<<<<

x==========x]
[2024-05-30 19:52:45,021: INFO: common: yaml file: config\config.yaml loaded successfully]
[2024-05-30 19:52:45,034: INFO: common: yaml file: params.yaml loaded successfully]
[2024-05-30 19:52:45,038: INFO: common: created directory at: artifacts]
[2024-05-30 19:52:45,038: INFO: common: created directory at: artifacts\training]
[2024-05-30 20:02:07,140: INFO: main: >>>>>> stage Data Ingestion stage started <<<<<<]
[2024-05-30 20:02:07,140: INFO: common: yaml file: config\config.yaml loaded successfully]
[2024-05-30 20:02:07,156: INFO: common: yaml file: params.yaml loaded successfully]
[2024-05-30 20:02:07,156: INFO: common: created directory at: artifacts]
[2024-05-30 20:02:07,156: INFO: common: created directory at: artifacts/data_ingestion]
[2024-05-30 20:02:07,156: INFO: data_ingestion: Downloading data from https://drive.google.com/file/d/1vlhZ5c7abUKF8xXERIw6m9Te8fW7ohw3/view?usp=sharing into file artifacts/data_ingestion/data.zip]
[2024-05-30 20:05:27,769: INFO: data_ingestion: Downloaded data from https://drive.google.com/file/d/1vlhZ5c7abUKF8xXERIw6m9Te8fW7ohw3/view?usp=sharing into file artifacts/data_ingestion/data.zip]
[2024-05-30 20:05:29,308: INFO: main: >>>>>> stage Data Ingestion stage completed <<<<<<

x==========x]
[2024-05-30 20:05:29,311: INFO: main: *******************]
[2024-05-30 20:05:29,311: INFO: main: >>>>>> stage Prepare base model started <<<<<<]
[2024-05-30 20:05:29,314: INFO: common: yaml file: config\config.yaml loaded successfully]
[2024-05-30 20:05:29,327: INFO: common: yaml file: params.yaml loaded successfully]
[2024-05-30 20:05:29,331: INFO: common: created directory at: artifacts]
[2024-05-30 20:05:29,332: INFO: common: created directory at: artifacts/prepare_base_model]
[2024-05-30 20:05:30,604: WARNING: saving_utils: Compiled the loaded model, but the compiled metrics have yet to be built. `model.compile_metrics` will be empty until you train or evaluate the model.]
[2024-05-30 20:05:31,017: INFO: main: >>>>>> stage Prepare base model completed <<<<<<

x==========x]
[2024-05-30 20:05:31,017: INFO: main: *******************]
[2024-05-30 20:05:31,017: INFO: main: >>>>>> stage Training started <<<<<<]
[2024-05-30 20:05:31,017: ERROR: main: name 'ModelTrainingPipeline' is not defined]
Traceback (most recent call last):
  File "main.py", line 38, in <module>
    model_trainer = ModelTrainingPipeline()
NameError: name 'ModelTrainingPipeline' is not defined
[2024-05-30 20:07:03,801: INFO: main: >>>>>> stage Data Ingestion stage started <<<<<<]
[2024-05-30 20:07:03,801: INFO: common: yaml file: config\config.yaml loaded successfully]
[2024-05-30 20:07:03,818: INFO: common: yaml file: params.yaml loaded successfully]
[2024-05-30 20:07:03,818: INFO: common: created directory at: artifacts]
[2024-05-30 20:07:03,818: INFO: common: created directory at: artifacts/data_ingestion]
[2024-05-30 20:07:03,818: INFO: data_ingestion: Downloading data from https://drive.google.com/file/d/1vlhZ5c7abUKF8xXERIw6m9Te8fW7ohw3/view?usp=sharing into file artifacts/data_ingestion/data.zip]
[2024-05-30 20:10:46,225: INFO: data_ingestion: Downloaded data from https://drive.google.com/file/d/1vlhZ5c7abUKF8xXERIw6m9Te8fW7ohw3/view?usp=sharing into file artifacts/data_ingestion/data.zip]
[2024-05-30 20:10:47,629: INFO: main: >>>>>> stage Data Ingestion stage completed <<<<<<

x==========x]
[2024-05-30 20:10:47,630: INFO: main: *******************]
[2024-05-30 20:10:47,632: INFO: main: >>>>>> stage Prepare base model started <<<<<<]
[2024-05-30 20:10:47,635: INFO: common: yaml file: config\config.yaml loaded successfully]
[2024-05-30 20:10:47,635: INFO: common: yaml file: params.yaml loaded successfully]
[2024-05-30 20:10:47,635: INFO: common: created directory at: artifacts]
[2024-05-30 20:10:47,635: INFO: common: created directory at: artifacts/prepare_base_model]
[2024-05-30 20:10:48,711: WARNING: saving_utils: Compiled the loaded model, but the compiled metrics have yet to be built. `model.compile_metrics` will be empty until you train or evaluate the model.]
[2024-05-30 20:10:49,172: INFO: main: >>>>>> stage Prepare base model completed <<<<<<

x==========x]
[2024-05-30 20:10:49,188: INFO: main: *******************]
[2024-05-30 20:10:49,188: INFO: main: >>>>>> stage Training started <<<<<<]
[2024-05-30 20:10:49,188: INFO: common: yaml file: config\config.yaml loaded successfully]
[2024-05-30 20:10:49,197: INFO: common: yaml file: params.yaml loaded successfully]
[2024-05-30 20:10:49,197: INFO: common: created directory at: artifacts]
[2024-05-30 20:10:49,197: ERROR: main: name 'os' is not defined]
Traceback (most recent call last):
  File "main.py", line 40, in <module>
    model_trainer.main()
  File "e:\kidney-disease-classificatin-deep-learning-project\src\cnnClassifier\pipeline\stage_03_model_training.py", line 17, in main
    training_config = config.get_training_config()
  File "e:\kidney-disease-classificatin-deep-learning-project\src\cnnClassifier\config\configuration.py", line 61, in get_training_config
    training_data = os.path.join(self.config.data_ingestion.unzip_dir, "kidney-ct-scan-image")
NameError: name 'os' is not defined
[2024-05-30 20:16:40,801: INFO: main: >>>>>> stage Data Ingestion stage started <<<<<<]
[2024-05-30 20:16:40,804: INFO: common: yaml file: config\config.yaml loaded successfully]
[2024-05-30 20:16:40,806: INFO: common: yaml file: params.yaml loaded successfully]
[2024-05-30 20:16:40,806: INFO: common: created directory at: artifacts]
[2024-05-30 20:16:40,806: INFO: common: created directory at: artifacts/data_ingestion]
[2024-05-30 20:16:40,806: INFO: data_ingestion: Downloading data from https://drive.google.com/file/d/1vlhZ5c7abUKF8xXERIw6m9Te8fW7ohw3/view?usp=sharing into file artifacts/data_ingestion/data.zip]
[2024-05-30 20:19:01,048: INFO: data_ingestion: Downloaded data from https://drive.google.com/file/d/1vlhZ5c7abUKF8xXERIw6m9Te8fW7ohw3/view?usp=sharing into file artifacts/data_ingestion/data.zip]
[2024-05-30 20:19:02,460: INFO: main: >>>>>> stage Data Ingestion stage completed <<<<<<

x==========x]
[2024-05-30 20:19:02,460: INFO: main: *******************]
[2024-05-30 20:19:02,460: INFO: main: >>>>>> stage Prepare base model started <<<<<<]
[2024-05-30 20:19:02,467: INFO: common: yaml file: config\config.yaml loaded successfully]
[2024-05-30 20:19:02,467: INFO: common: yaml file: params.yaml loaded successfully]
[2024-05-30 20:19:02,467: INFO: common: created directory at: artifacts]
[2024-05-30 20:19:02,467: INFO: common: created directory at: artifacts/prepare_base_model]
[2024-05-30 20:19:03,589: WARNING: saving_utils: Compiled the loaded model, but the compiled metrics have yet to be built. `model.compile_metrics` will be empty until you train or evaluate the model.]
[2024-05-30 20:19:04,061: INFO: main: >>>>>> stage Prepare base model completed <<<<<<

x==========x]
[2024-05-30 20:19:04,073: INFO: main: *******************]
[2024-05-30 20:19:04,073: INFO: main: >>>>>> stage Training started <<<<<<]
[2024-05-30 20:19:04,077: INFO: common: yaml file: config\config.yaml loaded successfully]
[2024-05-30 20:19:04,077: INFO: common: yaml file: params.yaml loaded successfully]
[2024-05-30 20:19:04,077: INFO: common: created directory at: artifacts]
[2024-05-30 20:19:04,085: INFO: common: created directory at: artifacts\training]
[2024-05-30 20:22:06,598: INFO: main: >>>>>> stage Training completed <<<<<<

x==========x]
[2024-06-08 10:10:08,319: INFO: common: yaml file: config\config.yaml loaded successfully]
[2024-06-08 10:10:08,335: INFO: common: yaml file: params.yaml loaded successfully]
[2024-06-08 10:10:08,341: INFO: common: created directory at: artifacts]
[2024-06-08 10:10:36,375: INFO: common: json file saved at: scores.json]
[2024-06-08 10:14:42,230: INFO: common: yaml file: config\config.yaml loaded successfully]
[2024-06-08 10:14:42,232: INFO: common: yaml file: params.yaml loaded successfully]
[2024-06-08 10:14:42,240: INFO: common: created directory at: artifacts]
[2024-06-08 10:15:09,563: INFO: common: json file saved at: scores.json]
[2024-06-08 10:16:51,392: WARNING: connectionpool: Retrying (Retry(total=4, connect=5, read=4, redirect=5, status=5)) after connection broken by 'ConnectionResetError(10054, 'An existing connection was forcibly closed by the remote host', None, 10054, None)': /nikhilpawar2000/Kidney-Disease-classificatin-deep-learning-project.mlflow/api/2.0/mlflow/runs/create]
[2024-06-08 10:19:32,424: INFO: common: yaml file: config\config.yaml loaded successfully]
[2024-06-08 10:19:32,432: INFO: common: yaml file: params.yaml loaded successfully]
[2024-06-08 10:19:32,434: INFO: common: created directory at: artifacts]
[2024-06-08 10:20:00,214: INFO: common: json file saved at: scores.json]
[2024-06-08 10:27:44,703: INFO: common: yaml file: config\config.yaml loaded successfully]
[2024-06-08 10:27:44,717: INFO: common: yaml file: params.yaml loaded successfully]
[2024-06-08 10:27:44,721: INFO: common: created directory at: artifacts]
[2024-06-08 10:28:12,682: INFO: common: json file saved at: scores.json]
[2024-06-08 10:28:56,007: WARNING: connectionpool: Retrying (Retry(total=4, connect=5, read=4, redirect=5, status=5)) after connection broken by 'ConnectionResetError(10054, 'An existing connection was forcibly closed by the remote host', None, 10054, None)': /nikhilpawar2000/Kidney-Disease-classificatin-deep-learning-project.mlflow/api/2.0/mlflow/runs/create]
[2024-06-08 10:29:03,228: WARNING: save: Found untraced functions such as _jit_compiled_convolution_op, _jit_compiled_convolution_op, _jit_compiled_convolution_op, _jit_compiled_convolution_op, _jit_compiled_convolution_op while saving (showing 5 of 14). These functions will not be directly callable after loading.]
[2024-06-08 10:29:03,935: INFO: builder_impl: Assets written to: C:\Users\nikhi\AppData\Local\Temp\tmpbfocr51b\model\data\model\assets]
[2024-06-08 10:30:28,088: WARNING: connectionpool: Retrying (Retry(total=4, connect=5, read=4, redirect=5, status=5)) after connection broken by 'ConnectionResetError(10054, 'An existing connection was forcibly closed by the remote host', None, 10054, None)': /nikhilpawar2000/Kidney-Disease-classificatin-deep-learning-project.mlflow/api/2.0/mlflow-artifacts/artifacts/3b2250f5fae8458a89aa593ec979a1bb/5a268fdaf9e548d58aa346a1ec69d546/artifacts/model/data/model/variables/variables.data-00000-of-00001]
[2024-06-08 10:37:07,890: INFO: common: yaml file: config\config.yaml loaded successfully]
[2024-06-08 10:37:07,900: INFO: common: yaml file: params.yaml loaded successfully]
[2024-06-08 10:37:07,903: INFO: common: created directory at: artifacts]
[2024-06-08 10:37:33,527: INFO: common: json file saved at: scores.json]
[2024-06-08 10:37:37,712: WARNING: save: Found untraced functions such as _jit_compiled_convolution_op, _jit_compiled_convolution_op, _jit_compiled_convolution_op, _jit_compiled_convolution_op, _jit_compiled_convolution_op while saving (showing 5 of 14). These functions will not be directly callable after loading.]
[2024-06-08 10:37:38,367: INFO: builder_impl: Assets written to: C:\Users\nikhi\AppData\Local\Temp\tmpuypn2qrc\model\data\model\assets]
[2024-06-08 20:14:35,002: INFO: common: yaml file: config\config.yaml loaded successfully]
[2024-06-08 20:14:35,015: INFO: common: yaml file: params.yaml loaded successfully]
[2024-06-08 20:14:35,016: INFO: common: created directory at: artifacts]
[2024-06-08 20:15:03,184: INFO: common: json file saved at: scores.json]
[2024-06-08 20:15:10,249: WARNING: save: Found untraced functions such as _jit_compiled_convolution_op, _jit_compiled_convolution_op, _jit_compiled_convolution_op, _jit_compiled_convolution_op, _jit_compiled_convolution_op while saving (showing 5 of 14). These functions will not be directly callable after loading.]
[2024-06-08 20:15:11,412: INFO: builder_impl: Assets written to: C:\Users\nikhi\AppData\Local\Temp\tmpzvvfyl6r\model\data\model\assets]
[2024-06-08 20:27:52,279: WARNING: connectionpool: Retrying (Retry(total=4, connect=5, read=4, redirect=5, status=5)) after connection broken by 'ConnectionResetError(10054, 'An existing connection was forcibly closed by the remote host', None, 10054, None)': /nikhilpawar2000/Kidney-Disease-classificatin-deep-learning-project.mlflow/api/2.0/mlflow-artifacts/artifacts/3b2250f5fae8458a89aa593ec979a1bb/ddeb0d08033c43afb7e0307f0588d352/artifacts/model/data/model/variables/variables.data-00000-of-00001]
[2024-06-08 20:38:51,928: INFO: main: >>>>>> stage Data Ingestion stage started <<<<<<]
[2024-06-08 20:38:51,931: INFO: common: yaml file: config\config.yaml loaded successfully]
[2024-06-08 20:38:51,937: INFO: common: yaml file: params.yaml loaded successfully]
[2024-06-08 20:38:51,937: INFO: common: created directory at: artifacts]
[2024-06-08 20:38:51,937: INFO: common: created directory at: artifacts/data_ingestion]
[2024-06-08 20:38:51,937: INFO: data_ingestion: Downloading data from https://drive.google.com/file/d/1vlhZ5c7abUKF8xXERIw6m9Te8fW7ohw3/view?usp=sharing into file artifacts/data_ingestion/data.zip]
[2024-06-08 20:41:09,885: INFO: data_ingestion: Downloaded data from https://drive.google.com/file/d/1vlhZ5c7abUKF8xXERIw6m9Te8fW7ohw3/view?usp=sharing into file artifacts/data_ingestion/data.zip]
[2024-06-08 20:41:10,732: INFO: main: >>>>>> stage Data Ingestion stage completed <<<<<<

x==========x]
[2024-06-08 20:41:10,732: INFO: main: *******************]
[2024-06-08 20:41:10,732: INFO: main: >>>>>> stage Prepare base model started <<<<<<]
[2024-06-08 20:41:10,739: INFO: common: yaml file: config\config.yaml loaded successfully]
[2024-06-08 20:41:10,741: INFO: common: yaml file: params.yaml loaded successfully]
[2024-06-08 20:41:10,741: INFO: common: created directory at: artifacts]
[2024-06-08 20:41:10,741: INFO: common: created directory at: artifacts/prepare_base_model]
[2024-06-08 20:41:11,328: WARNING: saving_utils: Compiled the loaded model, but the compiled metrics have yet to be built. `model.compile_metrics` will be empty until you train or evaluate the model.]
[2024-06-08 20:41:11,629: INFO: main: >>>>>> stage Prepare base model completed <<<<<<

x==========x]
[2024-06-08 20:41:11,629: INFO: main: *******************]
[2024-06-08 20:41:11,629: INFO: main: >>>>>> stage Training started <<<<<<]
[2024-06-08 20:41:11,633: INFO: common: yaml file: config\config.yaml loaded successfully]
[2024-06-08 20:41:11,636: INFO: common: yaml file: params.yaml loaded successfully]
[2024-06-08 20:41:11,637: INFO: common: created directory at: artifacts]
[2024-06-08 20:41:11,637: INFO: common: created directory at: artifacts\training]
[2024-06-08 20:42:40,657: INFO: main: >>>>>> stage Training completed <<<<<<

x==========x]
[2024-06-08 20:42:40,657: INFO: main: *******************]
[2024-06-08 20:42:40,657: INFO: main: >>>>>> stage Evaluation stage started <<<<<<]
[2024-06-08 20:42:40,673: INFO: common: yaml file: config\config.yaml loaded successfully]
[2024-06-08 20:42:40,673: INFO: common: yaml file: params.yaml loaded successfully]
[2024-06-08 20:42:40,673: INFO: common: created directory at: artifacts]
[2024-06-08 20:43:08,276: INFO: common: json file saved at: scores.json]
[2024-06-08 20:43:08,276: INFO: common: json file saved at: scores.json]
[2024-06-08 20:43:08,276: INFO: main: >>>>>> stage Evaluation stage completed <<<<<<

x==========x]
[2024-06-12 09:24:52,197: INFO: stage_01_data_ingestion: >>>>>> stage Data Ingestion stage started <<<<<<]
[2024-06-12 09:24:52,197: INFO: common: yaml file: config\config.yaml loaded successfully]
[2024-06-12 09:24:52,197: INFO: common: yaml file: params.yaml loaded successfully]
[2024-06-12 09:24:52,197: INFO: common: created directory at: artifacts]
[2024-06-12 09:24:52,208: INFO: common: created directory at: artifacts/data_ingestion]
[2024-06-12 09:24:52,210: INFO: data_ingestion: Downloading data from https://drive.google.com/file/d/1vlhZ5c7abUKF8xXERIw6m9Te8fW7ohw3/view?usp=sharing into file artifacts/data_ingestion/data.zip]
[2024-06-12 09:53:07,693: INFO: _internal: [31m[1mWARNING: This is a development server. Do not use it in a production deployment. Use a production WSGI server instead.[0m
 * Running on all addresses (0.0.0.0)
 * Running on http://127.0.0.1:8080
 * Running on http://192.168.43.75:8080]
[2024-06-12 09:53:07,693: INFO: _internal: [33mPress CTRL+C to quit[0m]
[2024-06-12 09:58:23,732: INFO: _internal: 127.0.0.1 - - [12/Jun/2024 09:58:23] "GET / HTTP/1.1" 200 -]
[2024-06-12 10:05:34,574: ERROR: app: Exception on /predict [POST]]
Traceback (most recent call last):
  File "C:\Users\nikhi\anaconda3\envs\kidney\lib\site-packages\flask\app.py", line 2190, in wsgi_app
    response = self.full_dispatch_request()
  File "C:\Users\nikhi\anaconda3\envs\kidney\lib\site-packages\flask\app.py", line 1486, in full_dispatch_request
    rv = self.handle_user_exception(e)
  File "C:\Users\nikhi\anaconda3\envs\kidney\lib\site-packages\flask_cors\extension.py", line 178, in wrapped_function
    return cors_after_request(app.make_response(f(*args, **kwargs)))
  File "C:\Users\nikhi\anaconda3\envs\kidney\lib\site-packages\flask\app.py", line 1484, in full_dispatch_request
    rv = self.dispatch_request()
  File "C:\Users\nikhi\anaconda3\envs\kidney\lib\site-packages\flask\app.py", line 1469, in dispatch_request
    return self.ensure_sync(self.view_functions[rule.endpoint])(**view_args)
  File "C:\Users\nikhi\anaconda3\envs\kidney\lib\site-packages\flask_cors\decorator.py", line 130, in wrapped_function
    resp = make_response(f(*args, **kwargs))
  File "app.py", line 44, in predictRoute
    result = clApp.classifier.predict()
  File "e:\kidney-disease-classificatin-deep-learning-project\src\cnnClassifier\pipeline\prediction.py", line 16, in predict
    model = load_model(os.path.join("model", "model.h5"))
  File "C:\Users\nikhi\anaconda3\envs\kidney\lib\site-packages\keras\saving\saving_api.py", line 212, in load_model
    return legacy_sm_saving_lib.load_model(
  File "C:\Users\nikhi\anaconda3\envs\kidney\lib\site-packages\keras\utils\traceback_utils.py", line 70, in error_handler
    raise e.with_traceback(filtered_tb) from None
  File "C:\Users\nikhi\anaconda3\envs\kidney\lib\site-packages\keras\saving\legacy\save.py", line 230, in load_model
    raise IOError(
OSError: No file or directory found at model\model.h5
[2024-06-12 10:05:34,618: INFO: _internal: 127.0.0.1 - - [12/Jun/2024 10:05:34] "[35m[1mPOST /predict HTTP/1.1[0m" 500 -]
[2024-06-12 10:10:25,531: INFO: _internal: 127.0.0.1 - - [12/Jun/2024 10:10:25] "GET / HTTP/1.1" 200 -]
[2024-06-12 10:10:37,538: ERROR: app: Exception on /predict [POST]]
Traceback (most recent call last):
  File "C:\Users\nikhi\anaconda3\envs\kidney\lib\site-packages\flask\app.py", line 2190, in wsgi_app
    response = self.full_dispatch_request()
  File "C:\Users\nikhi\anaconda3\envs\kidney\lib\site-packages\flask\app.py", line 1486, in full_dispatch_request
    rv = self.handle_user_exception(e)
  File "C:\Users\nikhi\anaconda3\envs\kidney\lib\site-packages\flask_cors\extension.py", line 178, in wrapped_function
    return cors_after_request(app.make_response(f(*args, **kwargs)))
  File "C:\Users\nikhi\anaconda3\envs\kidney\lib\site-packages\flask\app.py", line 1484, in full_dispatch_request
    rv = self.dispatch_request()
  File "C:\Users\nikhi\anaconda3\envs\kidney\lib\site-packages\flask\app.py", line 1469, in dispatch_request
    return self.ensure_sync(self.view_functions[rule.endpoint])(**view_args)
  File "C:\Users\nikhi\anaconda3\envs\kidney\lib\site-packages\flask_cors\decorator.py", line 130, in wrapped_function
    resp = make_response(f(*args, **kwargs))
  File "app.py", line 44, in predictRoute
    result = clApp.classifier.predict()
  File "e:\kidney-disease-classificatin-deep-learning-project\src\cnnClassifier\pipeline\prediction.py", line 16, in predict
    model = load_model(os.path.join("model", "model.h5"))
  File "C:\Users\nikhi\anaconda3\envs\kidney\lib\site-packages\keras\saving\saving_api.py", line 212, in load_model
    return legacy_sm_saving_lib.load_model(
  File "C:\Users\nikhi\anaconda3\envs\kidney\lib\site-packages\keras\utils\traceback_utils.py", line 70, in error_handler
    raise e.with_traceback(filtered_tb) from None
  File "C:\Users\nikhi\anaconda3\envs\kidney\lib\site-packages\keras\saving\legacy\save.py", line 230, in load_model
    raise IOError(
OSError: No file or directory found at model\model.h5
[2024-06-12 10:10:37,538: INFO: _internal: 127.0.0.1 - - [12/Jun/2024 10:10:37] "[35m[1mPOST /predict HTTP/1.1[0m" 500 -]
[2024-06-12 10:14:45,270: INFO: _internal: [31m[1mWARNING: This is a development server. Do not use it in a production deployment. Use a production WSGI server instead.[0m
 * Running on all addresses (0.0.0.0)
 * Running on http://127.0.0.1:8080
 * Running on http://192.168.43.75:8080]
[2024-06-12 10:14:45,270: INFO: _internal: [33mPress CTRL+C to quit[0m]
[2024-06-12 10:14:45,764: INFO: _internal: 127.0.0.1 - - [12/Jun/2024 10:14:45] "GET / HTTP/1.1" 200 -]
[2024-06-12 10:14:55,727: INFO: _internal: 127.0.0.1 - - [12/Jun/2024 10:14:55] "GET / HTTP/1.1" 200 -]
[2024-06-12 10:15:08,506: ERROR: app: Exception on /predict [POST]]
Traceback (most recent call last):
  File "C:\Users\nikhi\anaconda3\envs\kidney\lib\site-packages\flask\app.py", line 2190, in wsgi_app
    response = self.full_dispatch_request()
  File "C:\Users\nikhi\anaconda3\envs\kidney\lib\site-packages\flask\app.py", line 1486, in full_dispatch_request
    rv = self.handle_user_exception(e)
  File "C:\Users\nikhi\anaconda3\envs\kidney\lib\site-packages\flask_cors\extension.py", line 178, in wrapped_function
    return cors_after_request(app.make_response(f(*args, **kwargs)))
  File "C:\Users\nikhi\anaconda3\envs\kidney\lib\site-packages\flask\app.py", line 1484, in full_dispatch_request
    rv = self.dispatch_request()
  File "C:\Users\nikhi\anaconda3\envs\kidney\lib\site-packages\flask\app.py", line 1469, in dispatch_request
    return self.ensure_sync(self.view_functions[rule.endpoint])(**view_args)
  File "C:\Users\nikhi\anaconda3\envs\kidney\lib\site-packages\flask_cors\decorator.py", line 130, in wrapped_function
    resp = make_response(f(*args, **kwargs))
  File "app.py", line 44, in predictRoute
    result = clApp.classifier.predict()
  File "e:\kidney-disease-classificatin-deep-learning-project\src\cnnClassifier\pipeline\prediction.py", line 16, in predict
    model = load_model(os.path.join("model", "model.h5"))
  File "C:\Users\nikhi\anaconda3\envs\kidney\lib\site-packages\keras\saving\saving_api.py", line 212, in load_model
    return legacy_sm_saving_lib.load_model(
  File "C:\Users\nikhi\anaconda3\envs\kidney\lib\site-packages\keras\utils\traceback_utils.py", line 70, in error_handler
    raise e.with_traceback(filtered_tb) from None
  File "C:\Users\nikhi\anaconda3\envs\kidney\lib\site-packages\keras\saving\legacy\save.py", line 230, in load_model
    raise IOError(
OSError: No file or directory found at model\model.h5
[2024-06-12 10:15:08,530: INFO: _internal: 127.0.0.1 - - [12/Jun/2024 10:15:08] "[35m[1mPOST /predict HTTP/1.1[0m" 500 -]
[2024-06-12 19:33:58,481: INFO: _internal: [31m[1mWARNING: This is a development server. Do not use it in a production deployment. Use a production WSGI server instead.[0m
 * Running on all addresses (0.0.0.0)
 * Running on http://127.0.0.1:8080
 * Running on http://192.168.43.75:8080]
[2024-06-12 19:33:58,482: INFO: _internal: [33mPress CTRL+C to quit[0m]
[2024-06-12 19:34:19,779: INFO: _internal: 127.0.0.1 - - [12/Jun/2024 19:34:19] "GET / HTTP/1.1" 200 -]
[2024-06-12 19:34:28,603: ERROR: app: Exception on /predict [POST]]
Traceback (most recent call last):
  File "C:\Users\nikhi\anaconda3\envs\kidney\lib\site-packages\flask\app.py", line 2190, in wsgi_app
    response = self.full_dispatch_request()
  File "C:\Users\nikhi\anaconda3\envs\kidney\lib\site-packages\flask\app.py", line 1486, in full_dispatch_request
    rv = self.handle_user_exception(e)
  File "C:\Users\nikhi\anaconda3\envs\kidney\lib\site-packages\flask_cors\extension.py", line 178, in wrapped_function
    return cors_after_request(app.make_response(f(*args, **kwargs)))
  File "C:\Users\nikhi\anaconda3\envs\kidney\lib\site-packages\flask\app.py", line 1484, in full_dispatch_request
    rv = self.dispatch_request()
  File "C:\Users\nikhi\anaconda3\envs\kidney\lib\site-packages\flask\app.py", line 1469, in dispatch_request
    return self.ensure_sync(self.view_functions[rule.endpoint])(**view_args)
  File "C:\Users\nikhi\anaconda3\envs\kidney\lib\site-packages\flask_cors\decorator.py", line 130, in wrapped_function
    resp = make_response(f(*args, **kwargs))
  File "app.py", line 44, in predictRoute
    result = clApp.classifier.predict()
  File "e:\kidney-disease-classificatin-deep-learning-project\src\cnnClassifier\pipeline\prediction.py", line 16, in predict
    model = load_model(os.path.join("model", "model.h5"))
  File "C:\Users\nikhi\anaconda3\envs\kidney\lib\site-packages\keras\saving\saving_api.py", line 212, in load_model
    return legacy_sm_saving_lib.load_model(
  File "C:\Users\nikhi\anaconda3\envs\kidney\lib\site-packages\keras\utils\traceback_utils.py", line 70, in error_handler
    raise e.with_traceback(filtered_tb) from None
  File "C:\Users\nikhi\anaconda3\envs\kidney\lib\site-packages\keras\saving\legacy\save.py", line 230, in load_model
    raise IOError(
OSError: No file or directory found at model\model.h5
[2024-06-12 19:34:28,627: INFO: _internal: 127.0.0.1 - - [12/Jun/2024 19:34:28] "[35m[1mPOST /predict HTTP/1.1[0m" 500 -]
[2024-06-12 19:36:57,179: INFO: _internal: 127.0.0.1 - - [12/Jun/2024 19:36:57] "GET / HTTP/1.1" 200 -]
[2024-06-12 19:37:31,035: INFO: _internal: [31m[1mWARNING: This is a development server. Do not use it in a production deployment. Use a production WSGI server instead.[0m
 * Running on all addresses (0.0.0.0)
 * Running on http://127.0.0.1:8080
 * Running on http://192.168.43.75:8080]
[2024-06-12 19:37:31,035: INFO: _internal: [33mPress CTRL+C to quit[0m]
[2024-06-12 19:37:45,717: WARNING: hdf5_format: No training configuration found in the save file, so the model was *not* compiled. Compile it manually.]
[2024-06-12 19:37:47,392: ERROR: app: Exception on /predict [POST]]
Traceback (most recent call last):
  File "C:\Users\nikhi\anaconda3\envs\kidney\lib\site-packages\flask\app.py", line 2190, in wsgi_app
    response = self.full_dispatch_request()
  File "C:\Users\nikhi\anaconda3\envs\kidney\lib\site-packages\flask\app.py", line 1486, in full_dispatch_request
    rv = self.handle_user_exception(e)
  File "C:\Users\nikhi\anaconda3\envs\kidney\lib\site-packages\flask_cors\extension.py", line 178, in wrapped_function
    return cors_after_request(app.make_response(f(*args, **kwargs)))
  File "C:\Users\nikhi\anaconda3\envs\kidney\lib\site-packages\flask\app.py", line 1484, in full_dispatch_request
    rv = self.dispatch_request()
  File "C:\Users\nikhi\anaconda3\envs\kidney\lib\site-packages\flask\app.py", line 1469, in dispatch_request
    return self.ensure_sync(self.view_functions[rule.endpoint])(**view_args)
  File "C:\Users\nikhi\anaconda3\envs\kidney\lib\site-packages\flask_cors\decorator.py", line 130, in wrapped_function
    resp = make_response(f(*args, **kwargs))
  File "app.py", line 44, in predictRoute
    result = clApp.classifier.predict()
  File "e:\kidney-disease-classificatin-deep-learning-project\src\cnnClassifier\pipeline\prediction.py", line 25, in predict
    if result[0] == 1:
ValueError: The truth value of an array with more than one element is ambiguous. Use a.any() or a.all()
[2024-06-12 19:37:47,392: INFO: _internal: 127.0.0.1 - - [12/Jun/2024 19:37:47] "[35m[1mPOST /predict HTTP/1.1[0m" 500 -]
[2024-06-12 19:38:46,112: INFO: _internal: 127.0.0.1 - - [12/Jun/2024 19:38:46] "GET / HTTP/1.1" 200 -]
[2024-06-12 19:38:59,341: WARNING: hdf5_format: No training configuration found in the save file, so the model was *not* compiled. Compile it manually.]
[2024-06-12 19:39:00,408: ERROR: app: Exception on /predict [POST]]
Traceback (most recent call last):
  File "C:\Users\nikhi\anaconda3\envs\kidney\lib\site-packages\flask\app.py", line 2190, in wsgi_app
    response = self.full_dispatch_request()
  File "C:\Users\nikhi\anaconda3\envs\kidney\lib\site-packages\flask\app.py", line 1486, in full_dispatch_request
    rv = self.handle_user_exception(e)
  File "C:\Users\nikhi\anaconda3\envs\kidney\lib\site-packages\flask_cors\extension.py", line 178, in wrapped_function
    return cors_after_request(app.make_response(f(*args, **kwargs)))
  File "C:\Users\nikhi\anaconda3\envs\kidney\lib\site-packages\flask\app.py", line 1484, in full_dispatch_request
    rv = self.dispatch_request()
  File "C:\Users\nikhi\anaconda3\envs\kidney\lib\site-packages\flask\app.py", line 1469, in dispatch_request
    return self.ensure_sync(self.view_functions[rule.endpoint])(**view_args)
  File "C:\Users\nikhi\anaconda3\envs\kidney\lib\site-packages\flask_cors\decorator.py", line 130, in wrapped_function
    resp = make_response(f(*args, **kwargs))
  File "app.py", line 44, in predictRoute
    result = clApp.classifier.predict()
  File "e:\kidney-disease-classificatin-deep-learning-project\src\cnnClassifier\pipeline\prediction.py", line 25, in predict
    if result[0] == 1:
ValueError: The truth value of an array with more than one element is ambiguous. Use a.any() or a.all()
[2024-06-12 19:39:00,408: INFO: _internal: 127.0.0.1 - - [12/Jun/2024 19:39:00] "[35m[1mPOST /predict HTTP/1.1[0m" 500 -]
[2024-06-12 19:49:51,236: INFO: main: >>>>>> stage Data Ingestion stage started <<<<<<]
[2024-06-12 19:49:51,251: INFO: common: yaml file: config\config.yaml loaded successfully]
[2024-06-12 19:49:51,266: INFO: common: yaml file: params.yaml loaded successfully]
[2024-06-12 19:49:51,275: INFO: common: created directory at: artifacts]
[2024-06-12 19:49:51,275: INFO: common: created directory at: artifacts/data_ingestion]
[2024-06-12 19:49:51,277: INFO: data_ingestion: Downloading data from https://drive.google.com/file/d/1vlhZ5c7abUKF8xXERIw6m9Te8fW7ohw3/view?usp=sharing into file artifacts/data_ingestion/data.zip]
[2024-06-12 19:51:09,194: INFO: data_ingestion: Downloaded data from https://drive.google.com/file/d/1vlhZ5c7abUKF8xXERIw6m9Te8fW7ohw3/view?usp=sharing into file artifacts/data_ingestion/data.zip]
[2024-06-12 19:51:10,037: INFO: main: >>>>>> stage Data Ingestion stage completed <<<<<<

x==========x]
[2024-06-12 19:51:10,043: INFO: main: *******************]
[2024-06-12 19:51:10,043: INFO: main: >>>>>> stage Prepare base model started <<<<<<]
[2024-06-12 19:51:10,044: INFO: common: yaml file: config\config.yaml loaded successfully]
[2024-06-12 19:51:10,051: INFO: common: yaml file: params.yaml loaded successfully]
[2024-06-12 19:51:10,052: INFO: common: created directory at: artifacts]
[2024-06-12 19:51:10,053: INFO: common: created directory at: artifacts/prepare_base_model]
[2024-06-12 19:51:10,653: WARNING: saving_utils: Compiled the loaded model, but the compiled metrics have yet to be built. `model.compile_metrics` will be empty until you train or evaluate the model.]
[2024-06-12 19:51:10,906: INFO: main: >>>>>> stage Prepare base model completed <<<<<<

x==========x]
[2024-06-12 19:51:10,906: INFO: main: *******************]
[2024-06-12 19:51:10,906: INFO: main: >>>>>> stage Training started <<<<<<]
[2024-06-12 19:51:10,910: INFO: common: yaml file: config\config.yaml loaded successfully]
[2024-06-12 19:51:10,912: INFO: common: yaml file: params.yaml loaded successfully]
[2024-06-12 19:51:10,912: INFO: common: created directory at: artifacts]
[2024-06-12 19:51:10,913: INFO: common: created directory at: artifacts\training]
[2024-06-12 19:52:43,994: INFO: main: >>>>>> stage Training completed <<<<<<

x==========x]
[2024-06-12 19:52:43,994: INFO: main: *******************]
[2024-06-12 19:52:43,994: INFO: main: >>>>>> stage Evaluation stage started <<<<<<]
[2024-06-12 19:52:43,996: INFO: common: yaml file: config\config.yaml loaded successfully]
[2024-06-12 19:52:44,002: INFO: common: yaml file: params.yaml loaded successfully]
[2024-06-12 19:52:44,002: INFO: common: created directory at: artifacts]
[2024-06-12 19:53:11,592: INFO: common: json file saved at: scores.json]
[2024-06-12 19:53:11,593: INFO: common: json file saved at: scores.json]
[2024-06-12 19:53:11,593: INFO: main: >>>>>> stage Evaluation stage completed <<<<<<

x==========x]
[2024-06-12 19:53:51,207: INFO: _internal: [31m[1mWARNING: This is a development server. Do not use it in a production deployment. Use a production WSGI server instead.[0m
 * Running on all addresses (0.0.0.0)
 * Running on http://127.0.0.1:8080
 * Running on http://192.168.43.75:8080]
[2024-06-12 19:53:51,207: INFO: _internal: [33mPress CTRL+C to quit[0m]
[2024-06-12 19:54:02,673: INFO: _internal: 127.0.0.1 - - [12/Jun/2024 19:54:02] "GET / HTTP/1.1" 200 -]
[2024-06-12 19:54:12,758: INFO: _internal: 127.0.0.1 - - [12/Jun/2024 19:54:12] "POST /predict HTTP/1.1" 200 -]
[2024-06-12 19:54:58,756: INFO: _internal: 127.0.0.1 - - [12/Jun/2024 19:54:58] "POST /predict HTTP/1.1" 200 -]
[2024-06-12 19:55:14,366: INFO: _internal: 127.0.0.1 - - [12/Jun/2024 19:55:14] "POST /predict HTTP/1.1" 200 -]
[2024-06-13 20:12:33,870: INFO: stage_01_data_ingestion: >>>>>> stage Data Ingestion stage started <<<<<<]
[2024-06-13 20:12:33,885: INFO: common: yaml file: config\config.yaml loaded successfully]
[2024-06-13 20:12:33,889: INFO: common: yaml file: params.yaml loaded successfully]
[2024-06-13 20:12:33,891: INFO: common: created directory at: artifacts]
[2024-06-13 20:12:33,891: INFO: common: created directory at: artifacts/data_ingestion]
[2024-06-13 20:12:33,891: INFO: data_ingestion: Downloading data from https://drive.google.com/file/d/1vlhZ5c7abUKF8xXERIw6m9Te8fW7ohw3/view?usp=sharing into file artifacts/data_ingestion/data.zip]
[2024-06-13 20:12:33,918: ERROR: stage_01_data_ingestion: HTTPSConnectionPool(host='drive.google.com', port=443): Max retries exceeded with url: /uc?/export=download&id=1vlhZ5c7abUKF8xXERIw6m9Te8fW7ohw3 (Caused by NameResolutionError("<urllib3.connection.HTTPSConnection object at 0x0000027B3849E310>: Failed to resolve 'drive.google.com' ([Errno 11001] getaddrinfo failed)"))]
Traceback (most recent call last):
  File "C:\Users\nikhi\anaconda3\envs\kidney\lib\site-packages\urllib3\connection.py", line 198, in _new_conn
    sock = connection.create_connection(
  File "C:\Users\nikhi\anaconda3\envs\kidney\lib\site-packages\urllib3\util\connection.py", line 60, in create_connection
    for res in socket.getaddrinfo(host, port, family, socket.SOCK_STREAM):
  File "C:\Users\nikhi\anaconda3\envs\kidney\lib\socket.py", line 918, in getaddrinfo
    for res in _socket.getaddrinfo(host, port, family, type, proto, flags):
socket.gaierror: [Errno 11001] getaddrinfo failed

The above exception was the direct cause of the following exception:

Traceback (most recent call last):
  File "C:\Users\nikhi\anaconda3\envs\kidney\lib\site-packages\urllib3\connectionpool.py", line 793, in urlopen
    response = self._make_request(
  File "C:\Users\nikhi\anaconda3\envs\kidney\lib\site-packages\urllib3\connectionpool.py", line 491, in _make_request
    raise new_e
  File "C:\Users\nikhi\anaconda3\envs\kidney\lib\site-packages\urllib3\connectionpool.py", line 467, in _make_request
    self._validate_conn(conn)
  File "C:\Users\nikhi\anaconda3\envs\kidney\lib\site-packages\urllib3\connectionpool.py", line 1099, in _validate_conn
    conn.connect()
  File "C:\Users\nikhi\anaconda3\envs\kidney\lib\site-packages\urllib3\connection.py", line 616, in connect
    self.sock = sock = self._new_conn()
  File "C:\Users\nikhi\anaconda3\envs\kidney\lib\site-packages\urllib3\connection.py", line 205, in _new_conn
    raise NameResolutionError(self.host, self, e) from e
urllib3.exceptions.NameResolutionError: <urllib3.connection.HTTPSConnection object at 0x0000027B3849E310>: Failed to resolve 'drive.google.com' ([Errno 11001] getaddrinfo failed)

The above exception was the direct cause of the following exception:

Traceback (most recent call last):
  File "C:\Users\nikhi\anaconda3\envs\kidney\lib\site-packages\requests\adapters.py", line 564, in send
    resp = conn.urlopen(
  File "C:\Users\nikhi\anaconda3\envs\kidney\lib\site-packages\urllib3\connectionpool.py", line 847, in urlopen
    retries = retries.increment(
  File "C:\Users\nikhi\anaconda3\envs\kidney\lib\site-packages\urllib3\util\retry.py", line 515, in increment
    raise MaxRetryError(_pool, url, reason) from reason  # type: ignore[arg-type]
urllib3.exceptions.MaxRetryError: HTTPSConnectionPool(host='drive.google.com', port=443): Max retries exceeded with url: /uc?/export=download&id=1vlhZ5c7abUKF8xXERIw6m9Te8fW7ohw3 (Caused by NameResolutionError("<urllib3.connection.HTTPSConnection object at 0x0000027B3849E310>: Failed to resolve 'drive.google.com' ([Errno 11001] getaddrinfo failed)"))

During handling of the above exception, another exception occurred:

Traceback (most recent call last):
  File "src/cnnClassifier/pipeline/stage_01_data_ingestion.py", line 25, in <module>
    obj.main()
  File "src/cnnClassifier/pipeline/stage_01_data_ingestion.py", line 16, in main
    data_ingestion.download_file()
  File "e:\kidney-disease-classificatin-deep-learning-project\src\cnnClassifier\components\data_ingestion.py", line 32, in download_file
    raise e
  File "e:\kidney-disease-classificatin-deep-learning-project\src\cnnClassifier\components\data_ingestion.py", line 27, in download_file
    gdown.download(prefix+file_id,zip_download_dir)
  File "C:\Users\nikhi\anaconda3\envs\kidney\lib\site-packages\gdown\download.py", line 202, in download
    res = sess.get(url, stream=True, verify=verify)
  File "C:\Users\nikhi\anaconda3\envs\kidney\lib\site-packages\requests\sessions.py", line 602, in get
    return self.request("GET", url, **kwargs)
  File "C:\Users\nikhi\anaconda3\envs\kidney\lib\site-packages\requests\sessions.py", line 589, in request
    resp = self.send(prep, **send_kwargs)
  File "C:\Users\nikhi\anaconda3\envs\kidney\lib\site-packages\requests\sessions.py", line 703, in send
    r = adapter.send(request, **kwargs)
  File "C:\Users\nikhi\anaconda3\envs\kidney\lib\site-packages\requests\adapters.py", line 597, in send
    raise ConnectionError(e, request=request)
requests.exceptions.ConnectionError: HTTPSConnectionPool(host='drive.google.com', port=443): Max retries exceeded with url: /uc?/export=download&id=1vlhZ5c7abUKF8xXERIw6m9Te8fW7ohw3 (Caused by NameResolutionError("<urllib3.connection.HTTPSConnection object at 0x0000027B3849E310>: Failed to resolve 'drive.google.com' ([Errno 11001] getaddrinfo failed)"))
[2024-06-13 20:13:42,139: INFO: stage_01_data_ingestion: >>>>>> stage Data Ingestion stage started <<<<<<]
[2024-06-13 20:13:42,144: INFO: common: yaml file: config\config.yaml loaded successfully]
[2024-06-13 20:13:42,146: INFO: common: yaml file: params.yaml loaded successfully]
[2024-06-13 20:13:42,146: INFO: common: created directory at: artifacts]
[2024-06-13 20:13:42,146: INFO: common: created directory at: artifacts/data_ingestion]
[2024-06-13 20:13:42,146: INFO: data_ingestion: Downloading data from https://drive.google.com/file/d/1vlhZ5c7abUKF8xXERIw6m9Te8fW7ohw3/view?usp=sharing into file artifacts/data_ingestion/data.zip]
[2024-06-13 20:13:42,159: ERROR: stage_01_data_ingestion: HTTPSConnectionPool(host='drive.google.com', port=443): Max retries exceeded with url: /uc?/export=download&id=1vlhZ5c7abUKF8xXERIw6m9Te8fW7ohw3 (Caused by NameResolutionError("<urllib3.connection.HTTPSConnection object at 0x000002FA59B660A0>: Failed to resolve 'drive.google.com' ([Errno 11001] getaddrinfo failed)"))]
Traceback (most recent call last):
  File "C:\Users\nikhi\anaconda3\envs\kidney\lib\site-packages\urllib3\connection.py", line 198, in _new_conn
    sock = connection.create_connection(
  File "C:\Users\nikhi\anaconda3\envs\kidney\lib\site-packages\urllib3\util\connection.py", line 60, in create_connection
    for res in socket.getaddrinfo(host, port, family, socket.SOCK_STREAM):
  File "C:\Users\nikhi\anaconda3\envs\kidney\lib\socket.py", line 918, in getaddrinfo
    for res in _socket.getaddrinfo(host, port, family, type, proto, flags):
socket.gaierror: [Errno 11001] getaddrinfo failed

The above exception was the direct cause of the following exception:

Traceback (most recent call last):
  File "C:\Users\nikhi\anaconda3\envs\kidney\lib\site-packages\urllib3\connectionpool.py", line 793, in urlopen
    response = self._make_request(
  File "C:\Users\nikhi\anaconda3\envs\kidney\lib\site-packages\urllib3\connectionpool.py", line 491, in _make_request
    raise new_e
  File "C:\Users\nikhi\anaconda3\envs\kidney\lib\site-packages\urllib3\connectionpool.py", line 467, in _make_request
    self._validate_conn(conn)
  File "C:\Users\nikhi\anaconda3\envs\kidney\lib\site-packages\urllib3\connectionpool.py", line 1099, in _validate_conn
    conn.connect()
  File "C:\Users\nikhi\anaconda3\envs\kidney\lib\site-packages\urllib3\connection.py", line 616, in connect
    self.sock = sock = self._new_conn()
  File "C:\Users\nikhi\anaconda3\envs\kidney\lib\site-packages\urllib3\connection.py", line 205, in _new_conn
    raise NameResolutionError(self.host, self, e) from e
urllib3.exceptions.NameResolutionError: <urllib3.connection.HTTPSConnection object at 0x000002FA59B660A0>: Failed to resolve 'drive.google.com' ([Errno 11001] getaddrinfo failed)

The above exception was the direct cause of the following exception:

Traceback (most recent call last):
  File "C:\Users\nikhi\anaconda3\envs\kidney\lib\site-packages\requests\adapters.py", line 564, in send
    resp = conn.urlopen(
  File "C:\Users\nikhi\anaconda3\envs\kidney\lib\site-packages\urllib3\connectionpool.py", line 847, in urlopen
    retries = retries.increment(
  File "C:\Users\nikhi\anaconda3\envs\kidney\lib\site-packages\urllib3\util\retry.py", line 515, in increment
    raise MaxRetryError(_pool, url, reason) from reason  # type: ignore[arg-type]
urllib3.exceptions.MaxRetryError: HTTPSConnectionPool(host='drive.google.com', port=443): Max retries exceeded with url: /uc?/export=download&id=1vlhZ5c7abUKF8xXERIw6m9Te8fW7ohw3 (Caused by NameResolutionError("<urllib3.connection.HTTPSConnection object at 0x000002FA59B660A0>: Failed to resolve 'drive.google.com' ([Errno 11001] getaddrinfo failed)"))

During handling of the above exception, another exception occurred:

Traceback (most recent call last):
  File "src/cnnClassifier/pipeline/stage_01_data_ingestion.py", line 25, in <module>
    obj.main()
  File "src/cnnClassifier/pipeline/stage_01_data_ingestion.py", line 16, in main
    data_ingestion.download_file()
  File "e:\kidney-disease-classificatin-deep-learning-project\src\cnnClassifier\components\data_ingestion.py", line 32, in download_file
    raise e
  File "e:\kidney-disease-classificatin-deep-learning-project\src\cnnClassifier\components\data_ingestion.py", line 27, in download_file
    gdown.download(prefix+file_id,zip_download_dir)
  File "C:\Users\nikhi\anaconda3\envs\kidney\lib\site-packages\gdown\download.py", line 202, in download
    res = sess.get(url, stream=True, verify=verify)
  File "C:\Users\nikhi\anaconda3\envs\kidney\lib\site-packages\requests\sessions.py", line 602, in get
    return self.request("GET", url, **kwargs)
  File "C:\Users\nikhi\anaconda3\envs\kidney\lib\site-packages\requests\sessions.py", line 589, in request
    resp = self.send(prep, **send_kwargs)
  File "C:\Users\nikhi\anaconda3\envs\kidney\lib\site-packages\requests\sessions.py", line 703, in send
    r = adapter.send(request, **kwargs)
  File "C:\Users\nikhi\anaconda3\envs\kidney\lib\site-packages\requests\adapters.py", line 597, in send
    raise ConnectionError(e, request=request)
requests.exceptions.ConnectionError: HTTPSConnectionPool(host='drive.google.com', port=443): Max retries exceeded with url: /uc?/export=download&id=1vlhZ5c7abUKF8xXERIw6m9Te8fW7ohw3 (Caused by NameResolutionError("<urllib3.connection.HTTPSConnection object at 0x000002FA59B660A0>: Failed to resolve 'drive.google.com' ([Errno 11001] getaddrinfo failed)"))
[2024-06-13 20:14:42,375: INFO: stage_01_data_ingestion: >>>>>> stage Data Ingestion stage started <<<<<<]
[2024-06-13 20:14:42,378: INFO: common: yaml file: config\config.yaml loaded successfully]
[2024-06-13 20:14:42,379: INFO: common: yaml file: params.yaml loaded successfully]
[2024-06-13 20:14:42,379: INFO: common: created directory at: artifacts]
[2024-06-13 20:14:42,379: INFO: common: created directory at: artifacts/data_ingestion]
[2024-06-13 20:14:42,379: INFO: data_ingestion: Downloading data from https://drive.google.com/file/d/1vlhZ5c7abUKF8xXERIw6m9Te8fW7ohw3/view?usp=sharing into file artifacts/data_ingestion/data.zip]
[2024-06-13 20:17:44,473: INFO: data_ingestion: Downloaded data from https://drive.google.com/file/d/1vlhZ5c7abUKF8xXERIw6m9Te8fW7ohw3/view?usp=sharing into file artifacts/data_ingestion/data.zip]
[2024-06-13 20:17:44,942: INFO: stage_01_data_ingestion: >>>>>> stage Data Ingestion stage completed <<<<<<

x==========x]
[2024-06-13 20:18:32,444: INFO: stage_01_data_ingestion: >>>>>> stage Data Ingestion stage started <<<<<<]
[2024-06-13 20:18:32,455: INFO: common: yaml file: config\config.yaml loaded successfully]
[2024-06-13 20:18:32,457: INFO: common: yaml file: params.yaml loaded successfully]
[2024-06-13 20:18:32,457: INFO: common: created directory at: artifacts]
[2024-06-13 20:18:32,457: INFO: common: created directory at: artifacts/data_ingestion]
[2024-06-13 20:18:32,457: INFO: data_ingestion: Downloading data from https://drive.google.com/file/d/1vlhZ5c7abUKF8xXERIw6m9Te8fW7ohw3/view?usp=sharing into file artifacts/data_ingestion/data.zip]
[2024-06-13 20:22:16,133: INFO: data_ingestion: Downloaded data from https://drive.google.com/file/d/1vlhZ5c7abUKF8xXERIw6m9Te8fW7ohw3/view?usp=sharing into file artifacts/data_ingestion/data.zip]
[2024-06-13 20:22:17,175: INFO: stage_01_data_ingestion: >>>>>> stage Data Ingestion stage completed <<<<<<

x==========x]
[2024-06-13 20:27:34,194: INFO: stage_01_data_ingestion: >>>>>> stage Data Ingestion stage started <<<<<<]
[2024-06-13 20:27:34,194: INFO: common: yaml file: config\config.yaml loaded successfully]
[2024-06-13 20:27:34,207: INFO: common: yaml file: params.yaml loaded successfully]
[2024-06-13 20:27:34,207: INFO: common: created directory at: artifacts]
[2024-06-13 20:27:34,208: INFO: common: created directory at: artifacts/data_ingestion]
[2024-06-13 20:27:34,208: INFO: data_ingestion: Downloading data from https://drive.google.com/file/d/1vlhZ5c7abUKF8xXERIw6m9Te8fW7ohw3/view?usp=sharing into file artifacts/data_ingestion/data.zip]
[2024-06-13 20:29:20,074: INFO: data_ingestion: Downloaded data from https://drive.google.com/file/d/1vlhZ5c7abUKF8xXERIw6m9Te8fW7ohw3/view?usp=sharing into file artifacts/data_ingestion/data.zip]
[2024-06-13 20:29:21,170: INFO: stage_01_data_ingestion: >>>>>> stage Data Ingestion stage completed <<<<<<

x==========x]
[2024-06-13 20:29:37,602: INFO: stage_02_prepare_base_model: *******************]
[2024-06-13 20:29:37,602: INFO: stage_02_prepare_base_model: >>>>>> stage Prepare base model started <<<<<<]
[2024-06-13 20:29:37,618: INFO: common: yaml file: config\config.yaml loaded successfully]
[2024-06-13 20:29:37,618: INFO: common: yaml file: params.yaml loaded successfully]
[2024-06-13 20:29:37,618: INFO: common: created directory at: artifacts]
[2024-06-13 20:29:37,618: INFO: common: created directory at: artifacts/prepare_base_model]
[2024-06-13 20:29:38,314: WARNING: saving_utils: Compiled the loaded model, but the compiled metrics have yet to be built. `model.compile_metrics` will be empty until you train or evaluate the model.]
[2024-06-13 20:29:38,842: INFO: stage_02_prepare_base_model: >>>>>> stage Prepare base model completed <<<<<<

x==========x]
[2024-06-13 20:29:45,668: INFO: stage_03_model_training: *******************]
[2024-06-13 20:29:45,668: INFO: stage_03_model_training: >>>>>> stage Training started <<<<<<]
[2024-06-13 20:29:45,682: INFO: common: yaml file: config\config.yaml loaded successfully]
[2024-06-13 20:29:45,682: INFO: common: yaml file: params.yaml loaded successfully]
[2024-06-13 20:29:45,682: INFO: common: created directory at: artifacts]
[2024-06-13 20:29:45,682: INFO: common: created directory at: artifacts\training]
[2024-06-13 21:58:21,373: INFO: stage_03_model_training: *******************]
[2024-06-13 21:58:21,373: INFO: stage_03_model_training: >>>>>> stage Training started <<<<<<]
[2024-06-13 21:58:21,378: INFO: common: yaml file: config\config.yaml loaded successfully]
[2024-06-13 21:58:21,386: INFO: common: yaml file: params.yaml loaded successfully]
[2024-06-13 21:58:21,387: INFO: common: created directory at: artifacts]
[2024-06-13 21:58:21,387: INFO: common: created directory at: artifacts\training]
[2024-06-13 22:08:05,453: INFO: stage_03_model_training: *******************]
[2024-06-13 22:08:05,453: INFO: stage_03_model_training: >>>>>> stage Training started <<<<<<]
[2024-06-13 22:08:05,453: INFO: common: yaml file: config\config.yaml loaded successfully]
[2024-06-13 22:08:05,453: INFO: common: yaml file: params.yaml loaded successfully]
[2024-06-13 22:08:05,453: INFO: common: created directory at: artifacts]
[2024-06-13 22:08:05,453: INFO: common: created directory at: artifacts\training]
[2024-06-13 22:16:14,999: INFO: stage_03_model_training: >>>>>> stage Training completed <<<<<<

x==========x]
[2024-06-13 22:16:29,175: INFO: stage_04_model_evaluation: *******************]
[2024-06-13 22:16:29,176: INFO: stage_04_model_evaluation: >>>>>> stage Evaluation stage started <<<<<<]
[2024-06-13 22:16:29,178: INFO: common: yaml file: config\config.yaml loaded successfully]
[2024-06-13 22:16:29,186: INFO: common: yaml file: params.yaml loaded successfully]
[2024-06-13 22:16:29,190: INFO: common: created directory at: artifacts]
[2024-06-13 22:16:57,857: INFO: common: json file saved at: scores.json]
[2024-06-13 22:16:57,857: INFO: common: json file saved at: scores.json]
[2024-06-13 22:16:57,864: INFO: stage_04_model_evaluation: >>>>>> stage Evaluation stage completed <<<<<<

x==========x]
